<?xml version="1.0"?>
<robot xmlns:xacro="http://www.ros.org/wiki/xacro" >

    <material name="white">
        <color rgba="1 1 1 1" />
    </material>

    <material name="orange">
        <color rgba="1 0.3 0.1 1"/>
    </material>

    <material name="blue">
        <color rgba="0.2 0.2 1 1"/>
    </material>

    <material name="black">
        <color rgba="0 0 0 1"/>
    </material>

    <material name="red">
        <color rgba="1 0 0 1"/>
    </material>
    
    <material name="green">
        <color rgba="0 1 0 1" />
    </material>

    <material name="gray">
        <color rgba="0.5 0.5 0.5 1" />
    </material>

    <material name="pink">
        <color rgba="1 0.4 0.7 1" />
    </material>
    <material name="cyan" >
    <color rgba="0.0 1.0 1.0 1.0" />
  </material>


    <!-- BASE LINK -->

    <link name="base_link">
    </link>

    <!-- ==================================================  BASE_FOOTPRINT joint, link ================================================== -->
    <joint name="base_footprint_joint" type="fixed">
        <parent link="base_link"/>
        <child link="base_footprint"/>
        <origin xyz="0 0 0" rpy="0 0 0"/>
    </joint>
    <!-- ================================================== -->

    <link name="base_footprint">
    </link>

    <!-- ==================================================  CHASSIS joint, link ================================================== -->
    <joint name="chassis_joint" type="fixed">
        <parent link="base_link"/>
        <child link="chassis"/>
        <origin xyz="0 0 0"/>
    </joint>
    <!-- ================================================== -->

    <link name="chassis">
        <visual>
            <origin xyz="-0.05 0 0.1" rpy="0 0 0"/>
            <geometry>
                <box size="0.6 0.5 0.15"/>
            </geometry>
            <material name="white"/>
        </visual>
        <collision>
            <origin xyz="0 0 0.075" rpy="0 0 0"/>
            <geometry>
                <box size="0.6 0.5 0.15"/>
            </geometry>
        </collision>
        <xacro:inertial_box mass="165.0" x="0.6" y="0.5" z="0.15">
            <origin xyz="0 0 0.075" rpy="0 0 0"/>
        </xacro:inertial_box>
    </link>
    <gazebo reference="chassis">
        <material>Gazebo/White</material>
        <mu1 value="0.5"/>
        <mu2 value="0.5"/>
    </gazebo>

    <!-- ================================================== LEFT BUMPER (Rounded Edge) ================================================== -->
    <joint name="left_bumper_joint" type="fixed">
        <parent link="chassis"/>
        <child link="left_bumper"/>
        <origin xyz="0.247 0.2 0.09" rpy="0 0 0"/>  
    </joint>
    <!-- ================================================== -->
    <link name="left_bumper">
        <visual>
            <geometry>
                <cylinder length="0.12" radius="0.05"/>  
            </geometry>
            <material name="white"/>
        </visual>
        <collision>
            <geometry>
                <cylinder length="0.12" radius="0.05"/>
            </geometry>
        </collision>
        <xacro:inertial_cylinder mass="10.0" length="0.12" radius="0.05">
            <origin xyz="0 0 0" rpy="0 0 0"/>
        </xacro:inertial_cylinder>
    </link>
    <gazebo reference="left_bumper">
        <material>Gazebo/White</material>
        <mu1 value="0.3"/>  
        <mu2 value="0.3"/>
    </gazebo>

    <!-- ================================================== RIGHT BUMPER (Rounded Edge) ================================================== -->
    <joint name="right_bumper_joint" type="fixed">
        <parent link="chassis"/>
        <child link="right_bumper"/>
        <origin xyz="0.247 -0.2 0.09" rpy="0 0 0"/>  
    </joint>
    <!-- ================================================== -->
    <link name="right_bumper">
        <visual>
            <geometry>
                <cylinder length="0.12" radius="0.05"/>
            </geometry>
            <material name="white"/>
        </visual>
        <collision>
            <geometry>
                <cylinder length="0.12" radius="0.05"/>
            </geometry>
        </collision>
        <xacro:inertial_cylinder mass="10.0" length="0.12" radius="0.05">
            <origin xyz="0 0 0" rpy="0 0 0"/>
        </xacro:inertial_cylinder>
    </link>
    <gazebo reference="right_bumper">
        <material>Gazebo/White</material>
        <mu1 value="0.3"/>
        <mu2 value="0.3"/>
    </gazebo>

    <!-- ==================================================  FRONT BUMPER joint, link ================================================== -->
    <joint name="front_bumper_joint" type="fixed">
        <parent link="base_link"/>
        <child link="front_bumper"/>
        <origin xyz="0 0 0"/>
    </joint>
    <!-- ================================================== -->

    <link name="front_bumper">
        <visual>
            <origin xyz="0.273 0 0.09" rpy="0 0 0"/>
            <geometry>
                <box size="0.05 0.4 0.1"/>
            </geometry>
            <material name="blue"/>
        </visual>
        <collision>
            <origin xyz="0 0 0.05" rpy="0 0 0"/>
            <geometry>
                <box size="0.05 0.4 0.1"/>
            </geometry>
        </collision>
        <xacro:inertial_box mass="10.0" x="0.05" y="0.4" z="0.1">
            <origin xyz="0 0 0.05" rpy="0 0 0"/>
        </xacro:inertial_box>
    </link>
    <gazebo reference="front_bumper">
        <material>Gazebo/Blue</material>
        <mu1 value="0.3"/>
        <mu2 value="0.3"/>
    </gazebo>

    <!-- ==================================================  FRONT LEFT WHEEL joint, link ================================================== -->
    <joint name="front_left_wheel_joint" type="continuous">
        <parent link="base_link"/>
        <child link="front_left_wheel"/>
        <origin xyz="0.17 0.225 0" rpy="-${pi/2} 0 0"/>
        <axis xyz="0 0 1"/>
    </joint>
    <!-- ================================================== -->

    <link name="front_left_wheel">
        <visual>
            <geometry>
                <cylinder length="0.07" radius="0.07" />
            </geometry>
            <material name="blue"/>
        </visual>
        <collision>
            <geometry>
                <cylinder length="0.075" radius="0.05" />
            </geometry>
        </collision>
        <xacro:inertial_cylinder mass="20.0" length="0.075" radius="0.07">
            <origin xyz="0 0 0" rpy="0 0 0"/>
        </xacro:inertial_cylinder>
    </link>
    <gazebo reference="front_left_wheel">
        <material>Gazebo/Blue</material>
        <mu1 value="0.8"/>
        <mu2 value="0.8"/>
    </gazebo>

    <!-- ==================================================  FRONT RIGHT WHEEL joint, link ================================================== -->
    <joint name="front_right_wheel_joint" type="continuous">
        <parent link="base_link"/>
        <child link="front_right_wheel"/>
        <origin xyz="0.17 -0.225 0" rpy="${pi/2} 0 0"/>
        <axis xyz="0 0 -1"/>
    </joint>
    <!-- ================================================== -->

    <link name="front_right_wheel">
        <visual>
            <geometry>
                <cylinder length="0.075" radius="0.07" />
            </geometry>
            <material name="blue"/>
        </visual>
        <collision>
            <geometry>
                <cylinder length="0.07" radius="0.07" />
            </geometry>
        </collision>
        <xacro:inertial_cylinder mass="20.0" length="0.075" radius="0.07">
            <origin xyz="0 0 0" rpy="0 0 0"/>
        </xacro:inertial_cylinder>
    </link>
    <gazebo reference="front_right_wheel">
        <material>Gazebo/Blue</material>
        <mu1 value="0.8"/>
        <mu2 value="0.8"/>
    </gazebo>

    <!-- ==================================================  BACK LEFT WHEEL joint, link ================================================== -->
    <joint name="back_left_wheel_joint" type="continuous">
        <parent link="base_link"/>
        <child link="back_left_wheel"/>
        <origin xyz="-0.09 0.225 0" rpy="-${pi/2} 0 0"/>
        <axis xyz="0 0 1"/>
    </joint>
    <!-- ================================================== -->

    <link name="back_left_wheel">
        <visual>
            <geometry>
                <cylinder length="0.075" radius="0.07" />
            </geometry>
            <material name="gray"/>
        </visual>
        <collision>
            <geometry>
                <cylinder length="0.075" radius="0.07" />
            </geometry>
        </collision>
        <xacro:inertial_cylinder mass="20.0" length="0.075" radius="0.07">
            <origin xyz="0 0 0" rpy="0 0 0"/>
        </xacro:inertial_cylinder>
    </link>
    <gazebo reference="back_left_wheel">
        <material>Gazebo/Gray</material>
        <mu1 value="0.5"/>
        <mu2 value="0.5"/>
    </gazebo>

    <!-- ================================================== BACK RIGHT WHEEL joint, link ================================================== -->
    <joint name="back_right_wheel_joint" type="continuous">
        <parent link="base_link"/>
        <child link="back_right_wheel"/>
        <origin xyz="-0.09 -0.225 0" rpy="${pi/2} 0 0"/>
        <axis xyz="0 0 -1"/>
    </joint>
    <!-- ================================================== -->

    <link name="back_right_wheel">
        <visual>
            <geometry>
                <cylinder length="0.075" radius="0.07" />
            </geometry>
            <material name="gray"/>
        </visual>
        <collision>
            <geometry>
                <cylinder length="0.075" radius="0.07" />
            </geometry>
        </collision>
        <xacro:inertial_cylinder mass="20.0" length="0.075" radius="0.07">
            <origin xyz="0 0 0" rpy="0 0 0"/>
        </xacro:inertial_cylinder>
    </link>
    <gazebo reference="back_right_wheel">
        <material>Gazebo/Gray</material>
        <mu1 value="0.5"/>
        <mu2 value="0.5"/>
    </gazebo>

    <!-- ================================================== REAR BACK LEFT WHEEL joint, link ================================================== -->
    <joint name="rear_back_left_wheel_joint" type="continuous">
        <parent link="base_link"/>
        <child link="rear_back_left_wheel"/>
        <origin xyz="-0.26 0.225 0" rpy="-${pi/2} 0 0"/>
        <axis xyz="0 0 1"/>
    </joint>
    <!-- ================================================== -->

    <link name="rear_back_left_wheel">
        <visual>
            <geometry>
                <cylinder length="0.075" radius="0.07" />
            </geometry>
            <material name="gray"/>
        </visual>
        <collision>
            <geometry>
                <cylinder length="0.075" radius="0.07" />
            </geometry>
        </collision>
        <xacro:inertial_cylinder mass="20.0" length="0.07" radius="0.07">
            <origin xyz="0 0 0" rpy="0 0 0"/>
        </xacro:inertial_cylinder>
    </link>
    <gazebo reference="rear_back_left_wheel">
        <material>Gazebo/Gray</material>
        <mu1 value="0.5"/> 
        <mu2 value="0.5"/> 
    </gazebo>

    <!-- ================================================== REAR BACK RIGHT WHEEL joint, link ================================================== -->
    <joint name="rear_back_right_wheel_joint" type="continuous">
        <parent link="base_link"/>
        <child link="rear_back_right_wheel"/>
        <origin xyz="-0.26 -0.225 0" rpy="${pi/2} 0 0"/>
        <axis xyz="0 0 -1"/>
    </joint>
    <!-- ================================================== -->

    <link name="rear_back_right_wheel">
        <visual>
            <geometry>
                <cylinder length="0.075" radius="0.07" />
            </geometry>
            <material name="gray"/>
        </visual>
        <collision>
            <geometry>
                <cylinder length="0.075" radius="0.07" />
            </geometry>
        </collision>
        <xacro:inertial_cylinder mass="20.0" length="0.075" radius="0.07">
            <origin xyz="0 0 0" rpy="0 0 0"/>
        </xacro:inertial_cylinder>
    </link>
    <gazebo reference="rear_back_right_wheel">
        <material>Gazebo/Gray</material>
        <mu1 value="0.5"/>
        <mu2 value="0.5"/>
    </gazebo>

<!--
<xacro:macro name="wheel_transmission" params="joint_name">
  <transmission name="${joint_name}_trans">
    <type>transmission_interface/SimpleTransmission</type>
    <joint name="${joint_name}">
      <hardware_interface>hardware_interface/VelocityJointInterface</hardware_interface>
    </joint>
    <actuator name="${joint_name}_actuator">
      <hardware_interface>hardware_interface/VelocityJointInterface</hardware_interface>
      <mechanical_reduction>1.0</mechanical_reduction>
    </actuator>
  </transmission>
</xacro:macro>
-->
<!-- Call for each wheel joint
<xacro:wheel_transmission joint_name="front_left_wheel_joint"/>
<xacro:wheel_transmission joint_name="front_right_wheel_joint"/>
<xacro:wheel_transmission joint_name="back_left_wheel_joint"/>
<xacro:wheel_transmission joint_name="back_right_wheel_joint"/>
<xacro:wheel_transmission joint_name="rear_back_left_wheel_joint"/>
<xacro:wheel_transmission joint_name="rear_back_right_wheel_joint"/>  -->

    
</robot>