<?xml version="1.0"?>
<robot xmlns:xacro="http://www.ros.org/wiki/xacro" >

    <material name="white">
        <color rgba="1 1 1 1" />
    </material>

    <material name="orange">
        <color rgba="1 0.3 0.1 1"/>
    </material>

    <material name="blue">
        <color rgba="0.2 0.2 1 1"/>
    </material>

    <material name="black">
        <color rgba="0 0 0 1"/>
    </material>

    <material name="red">
        <color rgba="1 0 0 1"/>
    </material>
    
    <material name="green">
        <color rgba="0 1 0 1" />
    </material>

    <material name="gray">
        <color rgba="0.5 0.5 0.5 1" />
    </material>

    <material name="pink">
        <color rgba="1 0.4 0.7 1" />
    </material>


    <!-- BASE LINK -->

    <link name="base_link">
    </link>

    <!-- ==================================================  BASE_FOOTPRINT joint, link ================================================== -->
    <joint name="base_footprint_joint" type="fixed">
        <parent link="base_link"/>
        <child link="base_footprint"/>
        <origin xyz="0 0 0" rpy="0 0 0"/>
    </joint>
    <!-- ================================================== -->

    <link name="base_footprint">
    </link>

    <!-- ==================================================  CHASSIS joint, link ================================================== -->
    <joint name="chassis_joint" type="fixed">
        <parent link="base_link"/>
        <child link="chassis"/>
        <origin xyz="0 0 0"/>
    </joint>
    <!-- ================================================== -->

    <link name="chassis">
        <visual>
            <origin xyz="0 0 0.1" rpy="0 0 0"/>
            <geometry>
                <box size="0.7 0.5 0.15"/>
            </geometry>
            <material name="white"/>
        </visual>
        <collision>
            <origin xyz="0 0 0.075" rpy="0 0 0"/>
            <geometry>
                <box size="0.7 0.5 0.15"/>
            </geometry>
        </collision>
        <xacro:inertial_box mass="0.8" x="0.7" y="0.5" z="0.15">
            <origin xyz="0 0 0.075" rpy="0 0 0"/>
        </xacro:inertial_box>
    </link>
    <gazebo reference="chassis">
        <material>Gazebo/White</material>
        <mu1 value="0.5"/>
        <mu2 value="0.5"/>
    </gazebo>

    <!-- ==================================================  FRONT LEFT WHEEL joint, link ================================================== -->
    <joint name="front_left_wheel_joint" type="continuous">
        <parent link="base_link"/>
        <child link="front_left_wheel"/>
        <origin xyz="0.17 0.225 0" rpy="-${pi/2} 0 0"/>
        <axis xyz="0 0 1"/>
    </joint>
    <!-- ================================================== -->

    <link name="front_left_wheel">
        <visual>
            <geometry>
                <cylinder length="0.07" radius="0.07" />
            </geometry>
            <material name="blue"/>
        </visual>
        <collision>
            <geometry>
                <cylinder length="0.075" radius="0.05" />
            </geometry>
        </collision>
        <xacro:inertial_cylinder mass="0.2" length="0.075" radius="0.07">
            <origin xyz="0 0 0" rpy="0 0 0"/>
        </xacro:inertial_cylinder>
    </link>
    <gazebo reference="front_left_wheel">
        <material>Gazebo/Blue</material>
        <mu1 value="0.8"/>
        <mu2 value="0.8"/>
    </gazebo>

    <!-- ==================================================  FRONT RIGHT WHEEL joint, link ================================================== -->
    <joint name="front_right_wheel_joint" type="continuous">
        <parent link="base_link"/>
        <child link="front_right_wheel"/>
        <origin xyz="0.17 -0.225 0" rpy="${pi/2} 0 0"/>
        <axis xyz="0 0 -1"/>
    </joint>
    <!-- ================================================== -->

    <link name="front_right_wheel">
        <visual>
            <geometry>
                <cylinder length="0.075" radius="0.07" />
            </geometry>
            <material name="blue"/>
        </visual>
        <collision>
            <geometry>
                <cylinder length="0.07" radius="0.07" />
            </geometry>
        </collision>
        <xacro:inertial_cylinder mass="0.2" length="0.075" radius="0.07">
            <origin xyz="0 0 0" rpy="0 0 0"/>
        </xacro:inertial_cylinder>
    </link>
    <gazebo reference="front_right_wheel">
        <material>Gazebo/Blue</material>
        <mu1 value="0.8"/>
        <mu2 value="0.8"/>
    </gazebo>

    <!-- ==================================================  BACK LEFT WHEEL joint, link ================================================== -->
    <joint name="back_left_wheel_joint" type="continuous">
        <parent link="base_link"/>
        <child link="back_left_wheel"/>
        <origin xyz="-0.09 0.225 0" rpy="-${pi/2} 0 0"/>
        <axis xyz="0 0 1"/>
    </joint>
    <!-- ================================================== -->

    <link name="back_left_wheel">
        <visual>
            <geometry>
                <cylinder length="0.075" radius="0.07" />
            </geometry>
            <material name="gray"/>
        </visual>
        <collision>
            <geometry>
                <cylinder length="0.075" radius="0.07" />
            </geometry>
        </collision>
        <xacro:inertial_cylinder mass="0.2" length="0.075" radius="0.07">
            <origin xyz="0 0 0" rpy="0 0 0"/>
        </xacro:inertial_cylinder>
    </link>
    <gazebo reference="back_left_wheel">
        <material>Gazebo/Gray</material>
        <mu1 value="0.5"/>
        <mu2 value="0.5"/>
    </gazebo>

    <!-- ================================================== BACK RIGHT WHEEL joint, link ================================================== -->
    <joint name="back_right_wheel_joint" type="continuous">
        <parent link="base_link"/>
        <child link="back_right_wheel"/>
        <origin xyz="-0.09 -0.225 0" rpy="${pi/2} 0 0"/>
        <axis xyz="0 0 -1"/>
    </joint>
    <!-- ================================================== -->

    <link name="back_right_wheel">
        <visual>
            <geometry>
                <cylinder length="0.075" radius="0.07" />
            </geometry>
            <material name="gray"/>
        </visual>
        <collision>
            <geometry>
                <cylinder length="0.075" radius="0.07" />
            </geometry>
        </collision>
        <xacro:inertial_cylinder mass="0.2" length="0.075" radius="0.07">
            <origin xyz="0 0 0" rpy="0 0 0"/>
        </xacro:inertial_cylinder>
    </link>
    <gazebo reference="back_right_wheel">
        <material>Gazebo/Gray</material>
        <mu1 value="0.5"/>
        <mu2 value="0.5"/>
    </gazebo>

    <!-- ================================================== REAR BACK LEFT WHEEL joint, link ================================================== -->
    <joint name="rear_back_left_wheel_joint" type="fixed">
        <parent link="base_link"/>
        <child link="rear_back_left_wheel"/>
        <origin xyz="-0.26 0.225 0.01" rpy="-${pi/2} 0 0"/>
        <!--axis xyz="0 0 1"/-->
    </joint>
    <!-- ================================================== -->

    <link name="rear_back_left_wheel">
        <visual>
            <geometry>
                <cylinder length="0.07" radius="0.06" />
            </geometry>
            <material name="gray"/>
        </visual>
        <collision>
            <geometry>
                <cylinder length="0.07" radius="0.06" />
            </geometry>
        </collision>
        <xacro:inertial_cylinder mass="0.2" length="0.07" radius="0.06">
            <origin xyz="0 0 0" rpy="0 0 0"/>
        </xacro:inertial_cylinder>
    </link>
    <gazebo reference="rear_back_left_wheel">
        <material>Gazebo/Gray</material>
        <mu1 value="0.3"/> 
        <mu2 value="0.3"/> 
    </gazebo>

    <!-- ================================================== REAR BACK RIGHT WHEEL joint, link ================================================== -->
    <joint name="rear_back_right_wheel_joint" type="fixed">
        <parent link="base_link"/>
        <child link="rear_back_right_wheel"/>
        <origin xyz="-0.26 -0.225 0.01" rpy="${pi/2} 0 0"/>
        <!--axis xyz="0 0 -1"/-->
    </joint>
    <!-- ================================================== -->

    <link name="rear_back_right_wheel">
        <visual>
            <geometry>
                <cylinder length="0.07" radius="0.06" />
            </geometry>
            <material name="gray"/>
        </visual>
        <collision>
            <geometry>
                <cylinder length="0.07" radius="0.06" />
            </geometry>
        </collision>
        <xacro:inertial_cylinder mass="0.2" length="0.07" radius="0.06">
            <origin xyz="0 0 0" rpy="0 0 0"/>
        </xacro:inertial_cylinder>
    </link>
    <gazebo reference="rear_back_right_wheel">
        <material>Gazebo/Gray</material>
        <mu1 value="0.3"/>
        <mu2 value="0.3"/>
    </gazebo>
    
</robot>